<?xml version="1.0" encoding="UTF-8"?>

<robot name="TUM">

  <link name="base_link">
    <inertial>
      <origin xyz="0 0 0" rpy="0 0 0" />
      <mass value="10" />
      <inertia ixx="0.5" ixy="0" ixz="0" iyy="0.5" iyz="0" izz="0.25" />
    </inertial>
    <visual>
      <origin xyz="0 0 0" rpy="0 0 0" />
      <geometry>
        <box size="0.5 0.5 0.25" />
      </geometry>
      <material name="black">
        <color rgba="0 0 0 1"/>
      </material>
    </visual>
    <collision>
      <origin xyz="0 0 0" rpy="0 0 0" />
      <geometry>
        <box size="0.5 0.5 0.25" />
      </geometry>
    </collision>
  </link>

  <link name="wheel1">
    <inertial>
      <origin xyz="0 0 0" rpy="0 0 0" />
      <mass value="1" />
      <inertia ixx="0.0001" ixy="0" ixz="0" iyy="0.1" iyz="0" izz="0.0002" />
    </inertial>
    <visual>
      <origin xyz="0 0.2 0.2" rpy="0 0 0" />
      <geometry>
        <cylinder length="0.2" radius="0.4" />
      </geometry>
      <material name="grey">
        <color rgba="1 1 1 1"/>
      </material>
    </visual>
    <collision>
      <origin xyz="0 0.2 0.2" rpy="0 0 0" />
      <geometry>
        <cylinder length="0.02" radius="0.4" />
      </geometry>
    </collision>
  </link>

  <joint name="joint_wheel1" type="continuous">
    <origin xyz="0 0.2 0.2" rpy="0 0 0" />
    <parent link="base_link" />
    <child link="wheel1" />
    <axis xyz="0 0 1" />
  </joint>

  <link name="wheel2">
    <inertial>
      <origin xyz="0 0 0" rpy="0 0 0" />
      <mass value="1" />
      <inertia ixx="0.0001" ixy="0" ixz="0" iyy="0.4" iyz="0" izz="0.0002" />
    </inertial>
    <visual>
      <origin xyz="0 0.4 0.2" rpy="0 0 0" />
      <geometry>
        <cylinder length="0.2" radius="0.4" />
      </geometry>
      <material name="grey">
        <color rgba="1 1 1 1"/>
      </material>
    </visual>
    <collision>
      <origin xyz="0 0.4 0.2" rpy="0 0 0" />
      <geometry>
        <cylinder length="0.2" radius="0.4" />
      </geometry>
    </collision>
  </link>

  <joint name="joint_wheel2" type="continuous">
    <origin xyz="0 0.4 0.2" rpy="0 0 0" />
    <parent link="base_link" />
    <child link="wheel2" />
    <axis xyz="0 0 1" />
  </joint>

  <link name="wheel3">
    <inertial>
      <origin xyz="0 0 0" rpy="0 0 0" />
      <mass value="1" />
      <inertia ixx="0.499" ixy="0" ixz="0" iyy="0.1" iyz="0" izz="0.0002" />
    </inertial>
    <visual>
      <origin xyz="0.499 0.2 .2" rpy="0 0 0" />
      <geometry>
        <cylinder length="0.2" radius="0.4" />
      </geometry>
      <material name="grey">
        <color rgba="1 1 1 1"/>
      </material>
    </visual>
    <collision>
      <origin xyz=".499 0.2 0.2" rpy="0 0 0" />
      <geometry>
        <cylinder length="0.2" radius="0.4" />
      </geometry>
    </collision>
  </link>

  <joint name="joint_wheel3" type="continuous">
    <origin xyz="0.499 0.2 0.2" rpy="0 0 0" />
    <parent link="base_link" />
    <child link="wheel3" />
    <axis xyz="0 0 1" />
  </joint>

  <link name="wheel4">
    <inertial>
      <origin xyz="0 0 0" rpy="0 0 0" />
      <mass value="1" />
      <inertia ixx="0.4999" ixy="0" ixz="0" iyy="0.4" iyz="0" izz="0.0002" />
    </inertial>
    <visual>
      <origin xyz="0.4999 0.4 0.2" rpy="0 0 0" />
      <geometry>
        <cylinder length="0.2" radius="0.4" />
      </geometry>
      <material name="grey">
        <color rgba="1 1 1 1"/>
      </material>
    </visual>
    <collision>
      <origin xyz="0.4999 0.4 0.2" rpy="0 0 0" />
      <geometry>
        <cylinder length="0.2" radius="0.4" />
      </geometry>
    </collision>
  </link>

  <joint name="joint_wheel4" type="continuous">
    <origin xyz="0.4999 0.4 0.2" rpy="0 0 0" />
    <parent link="base_link" />
    <child link="wheel4" />
    <axis xyz="0 0 1" />
  </joint>
</robot>
